Workbook

Sheet User Profiles
A1: UserID | B1: Name | C1: Surname | D1: Email | E1: Gender | F1: Race | G1: Age | H1: Province | I1: Social Media Handle
A2: 34 | B2: Chas | C2: Biggers | D2: Chas 351@yahoo.com | E2: male | F2: white | G2: 55 | H2: Free State | I2: @Chas 35 | J2: =VLOOKUP(A2,Viewership!A:A,1,FALSE) -> #N/A
A3: 39 | B3: Wilburn | C3: Crotty | D3: Wilburn 303@mail.com | E3: male | F3: black | G3: 54 | H3: Eastern Cape | I3: @Wilburn 30 | J3: =VLOOKUP(A3,Viewership!A:A,1,FALSE) -> #N/A
A4: 63 | B4: Emerson | C4: Slane | D4: Emerson 243@mail.com | E4: male | F4: black | G4: 51 | H4: Kwazulu Natal | I4: @Emerson 24 | J4: =VLOOKUP(A4,Viewership!A:A,1,FALSE) -> #N/A
A5: 90 | B5: Stacy | C5: Sytsma | D5: Stacy 273@mail.com | E5: male | F5: coloured | G5: 49 | H5: Kwazulu Natal | I5: @Stacy 27 | J5: =VLOOKUP(A5,Viewership!A:A,1,FALSE) -> #N/A
A6: 97 | B6: Lucas | C6: Woolard | D6: Lucas 233@mail.com | E6: male | F6: coloured | G6: 48 | H6: Free State | I6: @Lucas 23 | J6: =VLOOKUP(A6,Viewership!A:A,1,FALSE) -> 97
A7: 104 | B7: Randy | C7: Tancredi | D7: Randy 393@mail.com | E7: male | F7: black | G7: 47 | H7: Gauteng | I7: @Randy 39 | J7: =VLOOKUP(A7,Viewership!A:A,1,FALSE) -> #N/A
A8: 107 | B8: Trudie | C8: Restivo | D8: Trudie 502@gmail.com | E8: female | F8: black | G8: 47 | H8: Gauteng | I8: @Trudie 50 | J8: =VLOOKUP(A8,Viewership!A:A,1,FALSE) -> #N/A
A9: 108 | B9: Chas | C9: Luthy | D9: Chas 352@gmail.com | E9: male | F9: coloured | G9: 47 | H9: Western Cape | I9: @Chas 35 | J9: =VLOOKUP(A9,Viewership!A:A,1,FALSE) -> #N/A
A10: 120 | B10: Jared | C10: Bilyeu | D10: Jared 503@mail.com | E10: male | F10: coloured | G10: 46 | H10: Western Cape | I10: @Jared 50 | J10: =VLOOKUP(A10,Viewership!A:A,1,FALSE) -> #N/A
A11: 132 | B11: Carter | C11: Wigfall | D11: Carter 33@mail.com | E11: male | F11: black | G11: 45 | H11: Gauteng | I11: @Carter 3 | J11: =VLOOKUP(A11,Viewership!A:A,1,FALSE) -> 132
A12: 135 | B12: Emerson | C12: Beville | D12: Emerson 241@yahoo.com | E12: male | F12: other | G12: 45 | H12: Gauteng | I12: @Emerson 24 | J12: =VLOOKUP(A12,Viewership!A:A,1,FALSE) -> #N/A
A13: 138 | B13: Abel | C13: Hier | D13: Abel 185@mailxyz.com | E13: male | F13: None | G13: 45 | H13: Eastern Cape | I13: @Abel 18 | J13: =VLOOKUP(A13,Viewership!A:A,1,FALSE) -> #N/A
... A4322: 1133250 | B4322: Wilburn | C4322: Bilyeu | D4322: Wilburn 304@abcmail.com | E4322: male | F4322: indian_asian | G4322: 36 | H4322: Gauteng | I4322: @Wilburn 30 | J4322: =VLOOKUP(A4322,Viewership!A:A,1,FALSE) -> 1133250
A4323: 1280861 | B4323: None | C4323: None | D4323: Williemae 254@abcmail.com | G4323: 0 | I4323: None | J4323: =VLOOKUP(A4323,Viewership!A:A,1,FALSE) -> #N/A
A4324: 1281997 | B4324: Carlota | C4324: Tancredi | D4324: Carlota 273@mail.com | E4324: female | F4324: coloured | G4324: 14 | H4324: Free State | I4324: @Carlota 27 | J4324: =VLOOKUP(A4324,Viewership!A:A,1,FALSE) -> 1281997
A4325: 1283498 | B4325: None | C4325: None | D4325: Briana 62@gmail.com | G4325: 0 | I4325: None | J4325: =VLOOKUP(A4325,Viewership!A:A,1,FALSE) -> #N/A
A4326: 1285704 | B4326: None | C4326: None | D4326: Rebekah 464@abcmail.com | G4326: 0 | I4326: None | J4326: =VLOOKUP(A4326,Viewership!A:A,1,FALSE) -> #N/A
A4327: 1285929 | B4327: None | C4327: None | D4327: Lesli 65@mailxyz.com | G4327: 0 | I4327: None | J4327: =VLOOKUP(A4327,Viewership!A:A,1,FALSE) -> #N/A
A4328: 1285950 | B4328: Jared | C4328: Crotty | D4328: Jared 505@mailxyz.com | E4328: male | F4328: coloured | G4328: 30 | H4328: Mpumalanga | I4328: @Jared 50 | J4328: =VLOOKUP(A4328,Viewership!A:A,1,FALSE) -> #N/A
A4329: 1287933 | B4329: Kip | C4329: Arrieta | D4329: Kip 142@gmail.com | E4329: male | F4329: white | G4329: 26 | H4329: Northern Cape | I4329: @Kip 14 | J4329: =VLOOKUP(A4329,Viewership!A:A,1,FALSE) -> #N/A
A4330: 1292142 | B4330: None | C4330: None | D4330: Epifania 43@mail.com | G4330: 0 | I4330: None | J4330: =VLOOKUP(A4330,Viewership!A:A,1,FALSE) -> #N/A
A4331: 1293485 | B4331: Lane | C4331: Wigfall | D4331: Lane 113@mail.com | E4331: male | F4331: black | G4331: 21 | H4331: Gauteng | I4331: @Lane 11 | J4331: =VLOOKUP(A4331,Viewership!A:A,1,FALSE) -> #N/A
A4332: 1295130 | B4332: None | C4332: None | D4332: Dia 343@mail.com | G4332: 0 | I4332: None | J4332: =VLOOKUP(A4332,Viewership!A:A,1,FALSE) -> #N/A
A4333: 1297394 | B4333: None | C4333: None | D4333: Nubia 375@mailxyz.com | G4333: 0 | I4333: None | J4333: =VLOOKUP(A4333,Viewership!A:A,1,FALSE) -> #N/A
A4334: 1298176 | B4334: None | C4334: None | D4334: Lesli 405@mailxyz.com | G4334: 0 | I4334: None | J4334: =VLOOKUP(A4334,Viewership!A:A,1,FALSE) -> #N/A
A4335: 1299853 | B4335: Rebecka | C4335: Shkreli | D4335: Rebecka 313@mail.com | E4335: female | F4335: black | G4335: 22 | H4335: North West | I4335: @Rebecka 31 | J4335: =VLOOKUP(A4335,Viewership!A:A,1,FALSE) -> #N/A
A4336: 1303457 | B4336: None | C4336: None | D4336: Mellie 394@abcmail.com | G4336: 0 | I4336: None | J4336: =VLOOKUP(A4336,Viewership!A:A,1,FALSE) -> #N/A
A4337: 1304008 | B4337: None | C4337: None | D4337: Bess 61@yahoo.com | G4337: 0 | I4337: None | J4337: =VLOOKUP(A4337,Viewership!A:A,1,FALSE) -> #N/A
A4338: 1307720 | B4338: None | C4338: None | D4338: Lillian 95@mailxyz.com | G4338: 0 | I4338: None | J4338: =VLOOKUP(A4338,Viewership!A:A,1,FALSE) -> #N/A
A4339: 1308689 | B4339: None | C4339: None | D4339: Tiffani 383@mail.com | G4339: 0 | I4339: None | J4339: =VLOOKUP(A4339,Viewership!A:A,1,FALSE) -> #N/A
A4340: 1310414 | B4340: None | C4340: None | D4340: Nubia 483@mail.com | G4340: 0 | I4340: None | J4340: =VLOOKUP(A4340,Viewership!A:A,1,FALSE) -> #N/A
A4341: 1310589 | B4341: Michel | C4341: Langenfeld | D4341: Michel 203@mail.com | E4341: male | F4341: black | G4341: 33 | H4341: Mpumalanga | I4341: @Michel 20 | J4341: =VLOOKUP(A4341,Viewership!A:A,1,FALSE) -> #N/A
A4342: 1312534 | B4342: None | C4342: None | D4342: Trudie 44@abcmail.com | G4342: 0 | I4342: None | J4342: =VLOOKUP(A4342,Viewership!A:A,1,FALSE) -> #N/A
A4343: 1314312 | B4343: None | C4343: None | D4343: Nakita 462@gmail.com | G4343: 0 | I4343: None | J4343: =VLOOKUP(A4343,Viewership!A:A,1,FALSE) -> #N/A
A4344: 1315326 | B4344: None | C4344: None | D4344: Yolonda 365@mailxyz.com | G4344: 0 | I4344: None | J4344: =VLOOKUP(A4344,Viewership!A:A,1,FALSE) -> #N/A
A4345: 1316622 | B4345: None | C4345: None | D4345: Gretta 155@mailxyz.com | G4345: 0 | I4345: None | J4345: =VLOOKUP(A4345,Viewership!A:A,1,FALSE) -> #N/A
A4346: 1318133 | B4346: Romeo | C4346: Restivo | D4346: Romeo 372@gmail.com | E4346: male | F4346: other | G4346: 17 | H4346: Kwazulu Natal | I4346: @Romeo 37 | J4346: =VLOOKUP(A4346,Viewership!A:A,1,FALSE) -> #N/A
A4347: 1319265 | B4347: None | C4347: None | D4347: Seema 105@mailxyz.com | G4347: 0 | I4347: None | J4347: =VLOOKUP(A4347,Viewership!A:A,1,FALSE) -> #N/A
A4348: 1320407 | B4348: None | C4348: None | D4348: Iva 15@mailxyz.com | G4348: 0 | I4348: None | J4348: =VLOOKUP(A4348,Viewership!A:A,1,FALSE) -> #N/A
...

Sheet Viewership
A1: UserID | B1: Channel2 | C1: RecordDate2 | D1: Duration 2 | E1: userid
A2: 903994 | B2: Trace TV | C2: 42373.756 | D2: 0.0013888889 | E2: 903994 | F2: =VLOOKUP(A2,'User Profiles'!A:A,1,FALSE) -> 903994
A3: 802352 | B3: ICC Cricket World Cup 2011 | C3: 42459.378 | D3: 0.0070138889 | E3: 802352 | F3: =VLOOKUP(A3,'User Profiles'!A:A,1,FALSE) -> 802352
A4: 866125 | B4: ICC Cricket World Cup 2011 | C4: 42459.709 | D4: 0.00048611111 | E4: 866125 | F4: =VLOOKUP(A4,'User Profiles'!A:A,1,FALSE) -> 866125
A5: 2425604 | B5: ICC Cricket World Cup 2011 | C5: 42454.641 | D5: 0.00011574074 | E5: 2384970 | F5: =VLOOKUP(A5,'User Profiles'!A:A,1,FALSE) -> 2425604
A6: 793571 | B6: SawSee | C6: 42402.721 | D6: 0.0010763889 | E6: 793571 | F6: =VLOOKUP(A6,'User Profiles'!A:A,1,FALSE) -> 793571
A7: 793571 | B7: Boomerang | C7: 42447.706 | D7: 0.00011574074 | E7: 793571 | F7: =VLOOKUP(A7,'User Profiles'!A:A,1,FALSE) -> 793571
A8: 793571 | B8: Channel O | C8: 42449.184 | D8: 0.011979167 | E8: 793571 | F8: =VLOOKUP(A8,'User Profiles'!A:A,1,FALSE) -> 793571
A9: 793571 | B9: Boomerang | C9: 42403.28 | D9: 0.00084490741 | E9: 793571 | F9: =VLOOKUP(A9,'User Profiles'!A:A,1,FALSE) -> 793571
A10: 819248 | B10: Channel O | C10: 42460.417 | D10: 0.0032986111 | E10: 819248 | F10: =VLOOKUP(A10,'User Profiles'!A:A,1,FALSE) -> 819248
A11: 820321 | B11: Cartoon Network | C11: 42378.351 | D11: 0.00046296296 | E11: 820321 | F11: =VLOOKUP(A11,'User Profiles'!A:A,1,FALSE) -> 820321
A12: 892453 | B12: Supersport Live Events | C12: 42453.381 | D12: 6.9444444e-05 | E12: 892453 | F12: =VLOOKUP(A12,'User Profiles'!A:A,1,FALSE) -> 892453
A13: 892453 | B13: ICC Cricket World Cup 2011 | C13: 42455.648 | D13: 0.20916667 | E13: 892453 | F13: =VLOOKUP(A13,'User Profiles'!A:A,1,FALSE) -> 892453
... A10001: 810776 | B10001: SuperSport Blitz | C10001: 42422.315 | D10001: 0.00013888889 | E10001: 810776 | F10001: =VLOOKUP(A10001,'User Profiles'!A:A,1,FALSE) -> 810776
